//
//  NetworkManager.swift
//  GitInsider
//
//  Created by Alphan Og√ºn on 17.11.2023.
//

import Foundation
import Moya

enum NetworkError: Error {
    case invlalidData
}

protocol NetworkManaging {
    func request<T: Codable>(_ target: TargetType) async throws -> T
    func requestIsStatusValid(_ target: TargetType) async throws -> Bool
}

class NetworkManager: NetworkManaging {
    private let provider: MoyaProvider<MultiTarget>
    private let decoder: JSONDecoder
    
    init(provider: MoyaProvider<MultiTarget> = MoyaProvider(), decoder: JSONDecoder = JSONDecoder()) {
        self.provider = provider
        self.decoder = decoder
        
        decoder.keyDecodingStrategy = .convertFromSnakeCase
    }
    
    func request<T: Codable>(_ target: TargetType) async throws -> T {
        return try await withCheckedThrowingContinuation({ continuation in
            provider.request(MultiTarget(target)) { result in
                switch result {
                case .success(let response):
                    do {
                        let value = try self.decoder.decode(T.self, from: response.data)
                        continuation.resume(with: .success(value))
                    } catch {
                        continuation.resume(with: .failure(NetworkError.invlalidData))
                    }
                case .failure(let error):
                    continuation.resume(with: .failure(error))
                }
            }
        })
    }
    
    func requestIsStatusValid(_ target: TargetType) async throws -> Bool {
        return try await withCheckedThrowingContinuation({ continuation in
            provider.request(MultiTarget(target)) { result in
                switch result {
                case .success(let response):
                    if response.statusCode == 204 {
                        continuation.resume(with: .success(true))
                    } else {
                        continuation.resume(with: .success(false))
                    }
                case .failure(let error):
                    continuation.resume(with: .failure(error))
                }
            }
        })
    }
    
    
}
